Workbook
Name AhorroBase: OPEX_DET!$D$15
Name CAPEX_BASE: CAPEX_DET!$G$37
Name CAPEX_MULT: INPUTS!$B$32
Name CAPEX_TOTAL: CAPEX_DET!$G$38
Name CargaKW: INPUTS!$B$21
Name CargaKW_Real: INPUTS!$B$22
Name COP: INPUTS!$B$23
Name EficCaldera: INPUTS!$B$27
Name EscOPEX: INPUTS!$B$26
Name HorasAnio: INPUTS!$B$24
Name Horizonte: INPUTS!$B$10
Name PrecioElec: INPUTS!$B$25
Name PrecioGas: INPUTS!$B$28
Name ResetOn: INPUTS!$F$4
Name ResetSwitch: INPUTS!$B$4
Name SCEN_CAPEX_MULT: SCENARIOS!$B$4:$B$6
Name SCEN_ESCALO: SCENARIOS!$C$4:$C$6
Name SCEN_NAMES: SCENARIOS!$A$4:$A$6
Name SCEN_VALRES: SCENARIOS!$E$4:$E$6
Name SCEN_WACC: SCENARIOS!$D$4:$D$6
Name ScenarioSel: INPUTS!$B$6
Name TasaImpuesto: INPUTS!$B$15
Name TIR_OBJ: INPUTS!$B$17
Name ValorResidualPct: INPUTS!$B$16
Name WACC: INPUTS!$B$14

Sheet PORTADA
B6: ESTUDIO TÉCNICO-ECONÓMICO · BAXTER S.A. · PLANTA CALI
B7: Bomba de calor para tanque de condensados
B8: Memoria de cálculo económico · R2
B9: Análisis CAPEX, OPEX, VPN, TIR y Payback descontado · Horizonte 15 años · WACC 8 %
B10: Sustitución de caldera de vapor por sistema de bomba de calor industrial 250 kW (COP 3.0)
C14: CLIENTE | H14: UBICACIÓN
C15: Laboratorios BAXTER S.A. | H15: Planta Cali · Valle del Cauca · Colombia
C17: PREPARADO POR | H17: CÓDIGO DOC.
C18: E3PRO Engineering Solutions · DML Ingenieros | H18: W2601-PRMC-001-R3
C20: REVISIÓN | H20: FECHA EMISIÓN
C21: R3 · Corrección material vs R2 (cálculo VPN/TIR) | H21: 2026-05-02
C23: ESTADO | H23: CLASIFICACIÓN
C24: PARA APROBACIÓN | H24: Confidencial · Uso Interno
B27: RESUMEN EJECUTIVO · CIFRAS CLAVE
A29: VPN | D29: TIR | G29: PAYBACK | J29: CAPEX
A30: =INDICADORES!B4 -> 2004916.2 | D30: =INDICADORES!B5 -> 0.5898046 | G30: =INDICADORES!B6 -> 2.0259528 | J30: =INDICADORES!B12 -> 384561
A31: USD · Decisión: APROBAR | D31: Sobre objetivo del 8 % | G31: Recuperación capital | J31: USD · Inversión total
B34: CONTENIDO DEL DOCUMENTO
B35: DASHBOARD | C35: Dashboard ejecutivo · KPIs principales y comparación de escenarios
B36: DASH_FIN | C36: Dashboard financiero · Flujo de caja y sensibilidad ±25 %
B37: DASH_OPS | C37: Dashboard operativo y ambiental · OPEX caldera vs BC
B38: INPUTS | C38: Parámetros de entrada (editables)
B39: CAPEX_DET | C39: Desglose detallado del CAPEX
B40: OPEX_DET | C40: Desglose detallado del OPEX caldera vs bomba de calor
B41: CF_MODEL | C41: Modelo de flujo de caja descontado · 16 años
B42: INDICADORES | C42: KPIs financieros · VPN, TIR, Payback, Break-even
B43: SENS | C43: Análisis de sensibilidad detallado por variable
B46: © DML Ingenieros Consultores SAS · E3PRO Engineering Solutions · Cali, Colombia

Sheet DASHBOARD
A2: Dashboard Ejecutivo · Bomba de Calor para Tanque de Condensados | J2: W2601-PRMC-001-R2
A3: Cliente: Laboratorios BAXTER S.A. · Planta Cali · Estudio técnico-económico (15 años, WACC 8 %) | J3: =CONCATENATE("Escenario: ",ScenarioSel) -> Escenario: Base
A7: VPN (VALOR PRESENTE NETO) | D7: TIR (TASA INTERNA DE RETORNO) | G7: PAYBACK DESCONTADO | J7: CAPEX TOTAL
A8: =INDICADORES!B4 -> 2004916.2 | D8: =INDICADORES!B5 -> 0.5898046 | G8: =INDICADORES!B6 -> 2.0259528 | J8: =INDICADORES!B12 -> 384561
A9: USD · Decisión: APROBAR (VPN > 0) | D9: =CONCATENATE("Objetivo 8 % · TIR/Objetivo: ",TEXT(INDICADORES!B8,"0.0"),"×") -> Objetivo 8 % · TIR/Objetivo: 07× | G9: años · Benchmark sectorial 5–10 a | J9: USD · Incl. contingencia 8 %
A11: ANÁLISIS ECONÓMICO
A12: Composición del CAPEX por disciplina | G12: Comparación de escenarios (VPN)
A27: Flujo de caja descontado acumulado por escenario | G27: Resumen comparativo de escenarios
G29: ESCENARIO | H29: VPN (USD) | J29: TIR (%) | K29: PAYBACK
G30: Pesimista | H30: =_AUX!O3 -> 1229217.3 | J30: =_AUX!P3 -> 0.050363501 | K30: =_AUX!Q3 -> 2.5
G32: Base | H32: =_AUX!O4 -> 2079646.9 | J32: =_AUX!P4 -> 0.054941394 | K32: =_AUX!Q4 -> 1.5969046
G34: Optimista | H34: =_AUX!O5 -> 3163697.4 | J34: =_AUX!P5 -> 0.056528393 | K34: =_AUX!Q5 -> 1.2
G37: Δ-VPN positivo en todos los escenarios. Robustez sobre WACC, ahorro y horas de operación.
A44: DML Ingenieros Consultores SAS · E3PRO Engineering Solutions | G44: Revisión R3 · 2026-05-02 · Confidencial - Uso interno

Sheet DASH_FIN
A2: Dashboard Financiero · Flujo de Caja y Sensibilidad | J2: W2601-PRMC-001-R3
A3: Análisis de rentabilidad, cash flow descontado y sensibilidad de variables económicas | J3: =CONCATENATE("Horizonte: ",Horizonte," años · WACC: ",TEXT(WACC,"0%")) -> Horizonte: 15 años · WACC: 8%
A7: AHORRO AÑO 1 | D7: ROI AÑO 1 | G7: CAPEX INTENSIDAD | J7: NPV / CAPEX
A8: =INDICADORES!B13 -> 208000.61 | D8: =INDICADORES!B13/INDICADORES!B12 -> 0.54087805 | G8: =INDICADORES!B12/INDICADORES!B16 -> 1538.244 | J8: =INDICADORES!B4/INDICADORES!B12 -> 5.2135194
A9: USD/año · OPEX caldera vs bomba calor | D9: Ahorro/CAPEX (recuperación primer año) | G9: USD/kW · Benchmark 2 000–3 500 USD/kW | J9: Múltiplo · Creación de valor por USD invertido
A11: EVOLUCIÓN DE LA RENTABILIDAD
A12: Flujo de caja descontado anual y acumulado · Escenario Base | G12: Análisis de sensibilidad · Δ-VPN vs Base (±25 %)
A28: FLUJO DE CAJA DETALLADO · Escenario Base
A29: Tabla de Flujo de Caja descontado (15 años + año 0) | G29: Línea de break-even · CAPEX vs Ahorro acumulado
A30: Año | B30: CAPEX (USD) | C30: Ahorro OPEX (USD) | D30: FC bruto (USD) | E30: FC descontado | F30: FC acum. desc.
A31: 0 | B31: =CF_MODEL!B4 -> -384561 | C31: =CF_MODEL!B5+CF_MODEL!B6 -> 0 | D31: =CF_MODEL!B7 -> -384561 | E31: =CF_MODEL!B9 -> -384561 | F31: =CF_MODEL!B10 -> -384561
A32: 1 | B32: =CF_MODEL!C4 -> 0 | C32: =CF_MODEL!C5+CF_MODEL!C6 -> 208000.61 | D32: =CF_MODEL!C7 -> 208000.61 | E32: =CF_MODEL!C9 -> 192593.15 | F32: =CF_MODEL!C10 -> -191967.85
A33: 2 | B33: =CF_MODEL!D4 -> 0 | C33: =CF_MODEL!D5+CF_MODEL!D6 -> 218400.64 | D33: =CF_MODEL!D7 -> 218400.64 | E33: =CF_MODEL!D9 -> 187243.34 | F33: =CF_MODEL!D10 -> -4724.5041
A34: 3 | B34: =CF_MODEL!E4 -> 0 | C34: =CF_MODEL!E5+CF_MODEL!E6 -> 229320.67 | D34: =CF_MODEL!E7 -> 229320.67 | E34: =CF_MODEL!E9 -> 182042.14 | F34: =CF_MODEL!E10 -> 177317.63
A35: 4 | B35: =CF_MODEL!F4 -> 0 | C35: =CF_MODEL!F5+CF_MODEL!F6 -> 240786.7 | D35: =CF_MODEL!F7 -> 240786.7 | E35: =CF_MODEL!F9 -> 176985.41 | F35: =CF_MODEL!F10 -> 354303.05
A36: 5 | B36: =CF_MODEL!G4 -> 0 | C36: =CF_MODEL!G5+CF_MODEL!G6 -> 252826.04 | D36: =CF_MODEL!G7 -> 252826.04 | E36: =CF_MODEL!G9 -> 172069.15 | F36: =CF_MODEL!G10 -> 526372.2
A37: 6 | B37: =CF_MODEL!H4 -> 0 | C37: =CF_MODEL!H5+CF_MODEL!H6 -> 265467.34 | D37: =CF_MODEL!H7 -> 265467.34 | E37: =CF_MODEL!H9 -> 167289.45 | F37: =CF_MODEL!H10 -> 693661.65
A38: 7 | B38: =CF_MODEL!I4 -> 0 | C38: =CF_MODEL!I5+CF_MODEL!I6 -> 278740.7 | D38: =CF_MODEL!I7 -> 278740.7 | E38: =CF_MODEL!I9 -> 162642.52 | F38: =CF_MODEL!I10 -> 856304.18
A39: 8 | B39: =CF_MODEL!J4 -> 0 | C39: =CF_MODEL!J5+CF_MODEL!J6 -> 292677.74 | D39: =CF_MODEL!J7 -> 292677.74 | E39: =CF_MODEL!J9 -> 158124.68 | F39: =CF_MODEL!J10 -> 1014428.9
A40: 9 | B40: =CF_MODEL!K4 -> 0 | C40: =CF_MODEL!K5+CF_MODEL!K6 -> 307311.63 | D40: =CF_MODEL!K7 -> 307311.63 | E40: =CF_MODEL!K9 -> 153732.32 | F40: =CF_MODEL!K10 -> 1168161.2
A41: 10 | B41: =CF_MODEL!L4 -> 0 | C41: =CF_MODEL!L5+CF_MODEL!L6 -> 322677.21 | D41: =CF_MODEL!L7 -> 322677.21 | E41: =CF_MODEL!L9 -> 149461.98 | F41: =CF_MODEL!L10 -> 1317623.2
A42: 11 | B42: =CF_MODEL!M4 -> 0 | C42: =CF_MODEL!M5+CF_MODEL!M6 -> 338811.07 | D42: =CF_MODEL!M7 -> 338811.07 | E42: =CF_MODEL!M9 -> 145310.26 | F42: =CF_MODEL!M10 -> 1462933.4
A43: 12 | B43: =CF_MODEL!N4 -> 0 | C43: =CF_MODEL!N5+CF_MODEL!N6 -> 355751.62 | D43: =CF_MODEL!N7 -> 355751.62 | E43: =CF_MODEL!N9 -> 141273.86 | F43: =CF_MODEL!N10 -> 1604207.3
A44: 13 | B44: =CF_MODEL!O4 -> 0 | C44: =CF_MODEL!O5+CF_MODEL!O6 -> 373539.2 | D44: =CF_MODEL!O7 -> 373539.2 | E44: =CF_MODEL!O9 -> 137349.59 | F44: =CF_MODEL!O10 -> 1741556.9
A45: 14 | B45: =CF_MODEL!P4 -> 0 | C45: =CF_MODEL!P5+CF_MODEL!P6 -> 392216.16 | D45: =CF_MODEL!P7 -> 392216.16 | E45: =CF_MODEL!P9 -> 133534.32 | F45: =CF_MODEL!P10 -> 1875091.2
A46: 15 | B46: =CF_MODEL!Q4 -> 0 | C46: =CF_MODEL!Q5+CF_MODEL!Q6 -> 411826.97 | D46: =CF_MODEL!Q7 -> 411826.97 | E46: =CF_MODEL!Q9 -> 129825.04 | F46: =CF_MODEL!Q10 -> 2004916.2
A47: TOTALES (15 años) | B47: =SUM(B31:B46) -> -384561 | C47: =SUM(C31:C46) -> 4488354.3 | D47: =SUM(D31:D46) -> 4103793.3 | E47: =SUM(E31:E46) -> 2004916.2 | F47: =F46 -> 2004916.2
A50: DML Ingenieros Consultores SAS · E3PRO Engineering Solutions | G50: Revisión R3 · 2026-05-02 · Confidencial - Uso interno

Sheet DASH_OPS
A2: Dashboard Operativo y Ambiental · Justificación Técnica | J2: W2601-PRMC-001-R3
A3: Comparativa caldera vs bomba de calor · Reducción de OPEX, gas natural y emisiones de CO₂ | J3: =CONCATENATE("Carga: ",CargaKW," kW · COP: ",COP) -> Carga: 250 kW · COP: 3
A7: CO₂ EVITADO | D7: GAS NATURAL EVITADO | G7: EQUIVALENTE ÁRBOLES | J7: REDUCCIÓN OPEX
A8: =_AUX!I3-_AUX!J3 -> 309.7963 | D8: =_AUX!I4 -> 223803.25 | G8: =_AUX!I5 -> 13940.833 | J8: =1-(SUM(OPEX_DET!C2:C14)/SUM(OPEX_DET!B2:B14)) -> 0.68479482
A9: t CO₂ /año · Gas natural sustituido | D9: =CONCATENATE("m³/año · ",TEXT(INPUTS!B34,"#,##0")," COP/m³ × TRM ",TEXT(INPUTS!B35,"#,##0")) -> m³/año · 4000,0 COP/m³ × TRM 4277,370 | G9: árboles/año · Factor IPCC ~22 kg CO₂/árbol | J9: % · Bomba de calor vs caldera de vapor
A11: IMPACTO EN COSTOS DE OPERACIÓN · Precio gas: 4 000 COP/m³ estándar (TRM 4 277, PCS 38 MJ/m³)
A12: Comparativa OPEX por categoría · Caldera vs BC | G12: Composición del OPEX de la bomba de calor
A28: DESGLOSE DETALLADO Y PERFIL COMPARATIVO
A29: Detalle OPEX por concepto · Año 1 | G29: Perfil normalizado · Caldera vs BC (radar)
A30: Concepto | B30: Caldera (USD) | C30: BC (USD) | D30: Ahorro (USD) | E30: % del OPEX | F30: Reducción
A31: =OPEX_DET!A2 -> Costo energía | B31: =OPEX_DET!B2 -> 208189 | C31: =OPEX_DET!C2 -> 64759.814 | D31: =OPEX_DET!D2 -> 143429.18 | E31: =IFERROR(OPEX_DET!B2/SUM(OPEX_DET!B$2:B$14),0) -> 0.68541506 | F31: =IFERROR(1-OPEX_DET!C2/OPEX_DET!B2,0) -> 0.68893739
A32: =OPEX_DET!A3 -> Preventivo | B32: =OPEX_DET!B3 -> 18183.673 | C32: =OPEX_DET!C3 -> 7576.5306 | D32: =OPEX_DET!D3 -> 10607.143 | E32: =IFERROR(OPEX_DET!B3/SUM(OPEX_DET!B$2:B$14),0) -> 0.059865621 | F32: =IFERROR(1-OPEX_DET!C3/OPEX_DET!B3,0) -> 0.58333333
A33: =OPEX_DET!A4 -> Correctivo | B33: =OPEX_DET!B4 -> 12122.449 | C33: =OPEX_DET!C4 -> 3838.7755 | D33: =OPEX_DET!D4 -> 8283.6735 | E33: =IFERROR(OPEX_DET!B4/SUM(OPEX_DET!B$2:B$14),0) -> 0.039910414 | F33: =IFERROR(1-OPEX_DET!C4/OPEX_DET!B4,0) -> 0.68333333
A34: =OPEX_DET!A5 -> Inspecciones | B34: =OPEX_DET!B5 -> 8586.7347 | C34: =OPEX_DET!C5 -> 3232.6531 | D34: =OPEX_DET!D5 -> 5354.0816 | E34: =IFERROR(OPEX_DET!B5/SUM(OPEX_DET!B$2:B$14),0) -> 0.028269877 | F34: =IFERROR(1-OPEX_DET!C5/OPEX_DET!B5,0) -> 0.62352941
A35: =OPEX_DET!A6 -> Químicos caldera | B35: =OPEX_DET!B6 -> 6566.3265 | C35: =OPEX_DET!C6 -> 0 | D35: =OPEX_DET!D6 -> 6566.3265 | E35: =IFERROR(OPEX_DET!B6/SUM(OPEX_DET!B$2:B$14),0) -> 0.021618141 | F35: =IFERROR(1-OPEX_DET!C6/OPEX_DET!B6,0) -> 1
A36: =OPEX_DET!A7 -> Agua reposición sistema enfriamiento | B36: =OPEX_DET!B7 -> 15840 | C36: =OPEX_DET!C7 -> 2161.8367 | D36: =OPEX_DET!D7 -> 13678.163 | E36: =IFERROR(OPEX_DET!B7/SUM(OPEX_DET!B$2:B$14),0) -> 0.052149607 | F36: =IFERROR(1-OPEX_DET!C7/OPEX_DET!B7,0) -> 0.86352041
A37: =OPEX_DET!A8 -> Análisis calidad | B37: =OPEX_DET!B8 -> 3232.6531 | C37: =OPEX_DET!C8 -> 1818.3673 | D37: =OPEX_DET!D8 -> 1414.2857 | E37: =IFERROR(OPEX_DET!B8/SUM(OPEX_DET!B$2:B$14),0) -> 0.010642777 | F37: =IFERROR(1-OPEX_DET!C8/OPEX_DET!B8,0) -> 0.4375
A38: =OPEX_DET!A9 -> Operador | B38: =OPEX_DET!B9 -> 2790.6977 | C38: =OPEX_DET!C9 -> 0 | D38: =OPEX_DET!D9 -> 2790.6977 | E38: =IFERROR(OPEX_DET!B9/SUM(OPEX_DET!B$2:B$14),0) -> 0.0091877392 | F38: =IFERROR(1-OPEX_DET!C9/OPEX_DET!B9,0) -> 1
A39: =OPEX_DET!A10 -> Supervisión | B39: =OPEX_DET!B10 -> 8081.6327 | C39: =OPEX_DET!C10 -> 4040.8163 | D39: =OPEX_DET!D10 -> 4040.8163 | E39: =IFERROR(OPEX_DET!B10/SUM(OPEX_DET!B$2:B$14),0) -> 0.026606943 | F39: =IFERROR(1-OPEX_DET!C10/OPEX_DET!B10,0) -> 0.5
A40: =OPEX_DET!A11 -> Seguros | B40: =OPEX_DET!B11 -> 4242.8571 | C40: =OPEX_DET!C11 -> 2828.5714 | D40: =OPEX_DET!D11 -> 1414.2857 | E40: =IFERROR(OPEX_DET!B11/SUM(OPEX_DET!B$2:B$14),0) -> 0.013968645 | F40: =IFERROR(1-OPEX_DET!C11/OPEX_DET!B11,0) -> 0.33333333
A41: =OPEX_DET!A12 -> Certificaciones | B41: =OPEX_DET!B12 -> 3535.7143 | C41: =OPEX_DET!C12 -> 2121.4286 | D41: =OPEX_DET!D12 -> 1414.2857 | E41: =IFERROR(OPEX_DET!B12/SUM(OPEX_DET!B$2:B$14),0) -> 0.011640537 | F41: =IFERROR(1-OPEX_DET!C12/OPEX_DET!B12,0) -> 0.4
A42: =OPEX_DET!A13 -> Emisiones CO2 | B42: =OPEX_DET!B13 -> 10854.458 | C42: =OPEX_DET!C13 -> 3109.5504 | D42: =OPEX_DET!D13 -> 7744.9075 | E42: =IFERROR(OPEX_DET!B13/SUM(OPEX_DET!B$2:B$14),0) -> 0.035735841 | F42: =IFERROR(1-OPEX_DET!C13/OPEX_DET!B13,0) -> 0.7135232
A43: =OPEX_DET!A14 -> Gestión residuos | B43: =OPEX_DET!B14 -> 1515.3061 | C43: =OPEX_DET!C14 -> 252.55102 | D43: =OPEX_DET!D14 -> 1262.7551 | E43: =IFERROR(OPEX_DET!B14/SUM(OPEX_DET!B$2:B$14),0) -> 0.0049888017 | F43: =IFERROR(1-OPEX_DET!C14/OPEX_DET!B14,0) -> 0.83333333
A44: TOTAL | B44: =SUM(B31:B43) -> 303741.5 | C44: =SUM(C31:C43) -> 95740.895 | D44: =SUM(D31:D43) -> 208000.61 | E44: 1 | F44: =1-C44/B44 -> 0.68479482
A50: DML Ingenieros Consultores SAS · E3PRO Engineering Solutions | G50: Revisión R3 · 2026-05-02 · Confidencial - Uso interno

Sheet INPUTS
A1: Parámetros de entrada · Editables
A2: Modifique las celdas en la columna VALOR. Para resetear, seleccione "Sí" en C5.
A3: Parámetro | B3: Valor | C3: Estado / Default | D3: Notas | E3: Helpers
B4: No | E4: ResetOn (1/0) | F4: =IF($B$4="Sí",1,0) -> 0
A5: Escenario | B5: Seleccionado | C5: (Elige escenario o '(Manual)')
B6: Base
A10: Horizonte (años) | B10: =IF(ResetOn=1, DEFAULTS!$B$4, C10) -> 15 | C10: =DEFAULTS!$B$4 -> 15 | D10: Unidad: años
A14: WACC (tasa descuento nominal) | B14: =IF(ResetOn=1, DEFAULTS!$B$5, IF(ScenarioSel="(Manual)", C14, IFERROR(INDEX(SCEN_WACC, MATCH(ScenarioSel, SCEN_NAMES,0)), C14))) -> 0.08 | C14: =DEFAULTS!$B$5 -> 0.08 | D14: Unidad: %
A15: Tasa de impuesto efectiva | B15: =IF(ResetOn=1, DEFAULTS!$B$6, C15) -> 0 | C15: =DEFAULTS!$B$6 -> 0 | D15: Unidad: %
A16: Valor residual sobre CAPEX | B16: =IF(ResetOn=1, DEFAULTS!$B$7, IF(ScenarioSel="(Manual)", C16, IFERROR(INDEX(SCEN_VALRES, MATCH(ScenarioSel, SCEN_NAMES,0)), C16))) -> 0 | C16: =DEFAULTS!$B$7 -> 0 | D16: Unidad: %
A17: TIR objetivo (%) | B17: =IF(ResetOn=1, DEFAULTS!$B$14, C17) -> 0.08 | C17: =DEFAULTS!$B$14 -> 0.08 | D17: Unidad: %
A21: Carga térmica de diseño (kW) | B21: =IF(ResetOn=1, DEFAULTS!$B$8, C21) -> 250 | C21: =DEFAULTS!$B$8 -> 250 | D21: Unidad: kW
A22: Carga térmica real (kW) | B22: =IF(ResetOn=1, DEFAULTS!$B$9, C22) -> 234.4 | C22: =DEFAULTS!$B$9 -> 234.4 | D22: Unidad: kW
A23: COP conservador (adim.) | B23: =IF(ResetOn=1, DEFAULTS!$B$10, C23) -> 3 | C23: =DEFAULTS!$B$10 -> 3 | D23: Unidad: adim.
A24: Horas/año | B24: =IF(ResetOn=1, DEFAULTS!$B$11, C24) -> 7920 | C24: =DEFAULTS!$B$11 -> 7920 | D24: Unidad: h
A25: Precio electricidad (USD/kWh) | B25: =IF(ResetOn=1, DEFAULTS!$B$12, C25) -> 0.10465116 | C25: =DEFAULTS!$B$12 -> 0.10465116 | D25: Unidad: USD/kWh
A26: Escalamiento anual ahorro (%) | B26: =IF(ResetOn=1, DEFAULTS!$B$13, IF(ScenarioSel="(Manual)", C26, IFERROR(INDEX(SCEN_ESCALO, MATCH(ScenarioSel, SCEN_NAMES,0)), C26))) -> 0.05 | C26: =DEFAULTS!$B$13 -> 0.05 | D26: Unidad: %
A27: Eficiencia caldera referencia | B27: =IF(ResetOn=1, DEFAULTS!$B$15, C27) -> 0.79 | C27: =DEFAULTS!$B$15 -> 0.79 | D27: Unidad: %
A28: Precio gas natural (USD/kWh eq.) | B28: =B38 -> 0.088593544 | C28: =DEFAULTS!$B$16 -> 0.088593577 | D28: Derivado de fila 34 (COP/m³ estándar) — ver bloque al final
A32: Multiplicador CAPEX (x) | B32: =IF(ResetOn=1, 1, IF(ScenarioSel="(Manual)", C32, IFERROR(INDEX(SCEN_CAPEX_MULT, MATCH(ScenarioSel, SCEN_NAMES,0)), C32))) -> 1 | C32: =1 -> 1 | D32: Unidad: –
A33: Conversión costo gas natural — referencia cliente
A34: Precio gas natural (COP/m³ estándar) | B34: 4000 | C34: 4000 | D34: Valor declarado por BAXTER (factura GdN)
A35: TRM referencia (COP/USD) | B35: 4277.37 | C35: 4277.37 | D35: Calibrada para preservar PrecioGas USD/kWh eq.
A36: PCS gas natural (MJ/m³) | B36: 38 | C36: 38 | D36: Norma NTC 2604 · Gas natural Promigas/Vanti
A37: ↳ Equivalente (USD/m³) | B37: =B34/B35 -> 0.93515408 | D37: → COP/m³ ÷ TRM
A38: ↳ Equivalente (USD/kWh eq.) — alimenta el modelo | B38: =B34/B35*3.6/B36 -> 0.088593544 | D38: → USD/m³ × 3,6 / PCS · ver fila 28

Sheet CAPEX_DET
A1: Concepto | B1: Cantidad | C1: Costo Unit. | D1: Costo Total | E1: % Total | F1: % Δ Partida | G1: Total Ajustado
A2: EQUIPOS PRINCIPALES
A3: Sistema bomba calor 250 kW industrial (FOB) | B3: 1 | C3: 250000 | D3: =B3*C3 -> 250000 | E3: =D3/SUM(D3:D32) -> 0.70209928 | F3: 0 | G3: =D3*(1+F3) -> 250000
A4: INSTRUMENTACIÓN Y CONTROL
A5: SCADA WinCC RT (integración planta) | B5: 1 | C5: 10000 | D5: =B5*C5 -> 10000 | E5: =D5/SUM(D3:D32) -> 0.028083971 | F5: 0 | G5: =D5*(1+F5) -> 10000
A6: Analizador conductividad + pH (1×) | B6: 0 | C6: 3500 | D6: =B6*C6 -> 0 | E6: =D6/SUM(D3:D32) -> 0 | F6: 0 | G6: =D6*(1+F6) -> 0
A7: LOGÍSTICA Y ADUANAS
A8: Transporte marítimo a Colombia | B8: 1 | C8: 12000 | D8: =B8*C8 -> 12000 | E8: =D8/SUM(D3:D32) -> 0.033700765 | F8: 0 | G8: =D8*(1+F8) -> 12000
A9: Aranceles y trámites aduaneros | B9: 1 | C9: 10000 | D9: =B9*C9 -> 10000 | E9: =D9/SUM(D3:D32) -> 0.028083971 | F9: 0 | G9: =D9*(1+F9) -> 10000
A10: IVA 19 % sobre importación (no capex) | B10: 1 | C10: 0 | D10: =B10*C10 -> 0 | E10: =D10/SUM(D3:D32) -> 0 | F10: 0 | G10: =D10*(1+F10) -> 0
A11: Transporte terrestre a Cali | B11: 1 | C11: 5000 | D11: =B11*C11 -> 5000 | E11: =D11/SUM(D3:D32) -> 0.014041986 | F11: 0 | G11: =D11*(1+F11) -> 5000
A12: SISTEMAS AUXILIARES
A13: Tubería carbon steel DN50 caliente (150 m) | B13: 150 | C13: 25 | D13: =B13*C13 -> 3750 | E13: =D13/SUM(D3:D32) -> 0.010531489 | F13: 0 | G13: =D13*(1+F13) -> 3750
A14: Tubería carbon steel DN80 frío (150 m) | B14: 150 | C14: 35 | D14: =B14*C14 -> 5250 | E14: =D14/SUM(D3:D32) -> 0.014744085 | F14: 0 | G14: =D14*(1+F14) -> 5250
A15: Válvulas industriales DN50 caliente (12×) | B15: 4 | C15: 450 | D15: =B15*C15 -> 1800 | E15: =D15/SUM(D3:D32) -> 0.0050551148 | F15: 0 | G15: =D15*(1+F15) -> 1800
A16: Válvulas industriales DN80 frío (8×) | B16: 4 | C16: 700 | D16: =B16*C16 -> 2800 | E16: =D16/SUM(D3:D32) -> 0.0078635119 | F16: 0 | G16: =D16*(1+F16) -> 2800
A17: Conexiones y accesorios ASME B31.1 | B17: 1 | C17: 8000 | D17: =B17*C17 -> 8000 | E17: =D17/SUM(D3:D32) -> 0.022467177 | F17: 0 | G17: =D17*(1+F17) -> 8000
A18: Aislamiento térmico (200 m²) | B18: 45 | C18: 55 | D18: =B18*C18 -> 2475 | E18: =D18/SUM(D3:D32) -> 0.0069507828 | F18: 0 | G18: =D18*(1+F18) -> 2475
A19: INGENIERÍA
A20: Ingeniería conceptual (200 h) | B20: 0 | C20: 30 | D20: =B20*C20 -> 0 | E20: =D20/SUM(D3:D32) -> 0 | F20: 0 | G20: =D20*(1+F20) -> 0
A21: Ingeniería básica (600 h) | B21: 0 | C21: 30 | D21: =B21*C21 -> 0 | E21: =D21/SUM(D3:D32) -> 0 | F21: 0 | G21: =D21*(1+F21) -> 0
A22: Ingeniería de detalle (1,000 h) | B22: 0 | C22: 30 | D22: =B22*C22 -> 0 | E22: =D22/SUM(D3:D32) -> 0 | F22: 0 | G22: =D22*(1+F22) -> 0
A23: Gestión de proyecto | B23: 1 | C23: 5000 | D23: =B23*C23 -> 5000 | E23: =D23/SUM(D3:D32) -> 0.014041986 | F23: 0 | G23: =D23*(1+F23) -> 5000
A24: INSTALACIÓN
A25: Obra civil | B25: 1 | C25: 5000 | D25: =B25*C25 -> 5000 | E25: =D25/SUM(D3:D32) -> 0.014041986 | F25: 0 | G25: =D25*(1+F25) -> 5000
A26: Instalación mecánica | B26: 1 | C26: 15000 | D26: =B26*C26 -> 15000 | E26: =D26/SUM(D3:D32) -> 0.042125957 | F26: 0 | G26: =D26*(1+F26) -> 15000
A27: Instalación eléctrica | B27: 1 | C27: 5000 | D27: =B27*C27 -> 5000 | E27: =D27/SUM(D3:D32) -> 0.014041986 | F27: 0 | G27: =D27*(1+F27) -> 5000
A28: Integración hidráulica | B28: 0 | C28: 8000 | D28: =B28*C28 -> 0 | E28: =D28/SUM(D3:D32) -> 0 | F28: 0 | G28: =D28*(1+F28) -> 0
A29: PUESTA EN MARCHA
A30: Commissioning y arranque supervisado | B30: 1 | C30: 15000 | D30: =B30*C30 -> 15000 | E30: =D30/SUM(D3:D32) -> 0.042125957 | F30: 0 | G30: =D30*(1+F30) -> 15000
A31: Capacitación técnica | B31: 0 | C31: 12000 | D31: =B31*C31 -> 0 | E31: =D31/SUM(D3:D32) -> 0 | F31: 0 | G31: =D31*(1+F31) -> 0
A32: Soporte técnico primer año | B32: 0 | C32: 10000 | D32: =B32*C32 -> 0 | E32: =D32/SUM(D3:D32) -> 0 | F32: 0 | G32: =D32*(1+F32) -> 0
A34: Subtotal | G34: =SUM(G3:G32) -> 356075
A35: Contingencia técnica (%) | F35: 0.08 | G35: =G34*F35 -> 28486
A36: Escalación precios (%) | F36: 0 | G36: =G34*F36 -> 0
A37: TOTAL CAPEX (ajustado, sin escenario) | G37: =G34+G35+G36 -> 384561
A38: TOTAL CAPEX (con escenario) | G38: =G37*CAPEX_MULT -> 384561
A39: CAPEX/kW diseño (USD/kW) | F39: Benchmark: 2.000–3.500 | G39: =G37/CargaKW -> 1538.244

Sheet OPEX_FACTORES
A1: Factores base OPEX (plantilla 2025BC escalada)
A3: Concepto | B3: Base Gas (USD) | C3: Base BC (USD) | D3: Unidad | E3: Notas | F3: Ratio plantilla | G3: =(CargaKW*HorasAnio)/(490*4000) -> 1.0102041 | H3: (escala costos lineales con la energía anual entregada)
A4: Costo energía | B4: =(CargaKW_Real/EficCaldera)*HorasAnio*PrecioGas -> 208189 | C4: =(CargaKW_Real/COP)*HorasAnio*PrecioElec -> 64759.814 | D4: USD/año | E4: Fórmula exacta desde INPUTS
A5: Preventivo | B5: 18000 | C5: 7500 | D5: USD/año | E5: Base plantilla 2025BC × ratio
A6: Correctivo | B6: 12000 | C6: 3800 | D6: USD/año | E6: Base plantilla 2025BC × ratio
A7: Inspecciones | B7: 8500 | C7: 3200 | D7: USD/año | E7: Base plantilla 2025BC × ratio
A8: Químicos caldera | B8: 6500 | C8: 0 | D8: USD/año | E8: Base plantilla 2025BC × ratio
A9: Agua reposición sistema enfriamiento | B9: 15680 | C9: 2140 | D9: USD/año | E9: Base plantilla 2025BC × ratio
A10: Análisis calidad | B10: 3200 | C10: 1800 | D10: USD/año | E10: Base plantilla 2025BC × ratio
A11: Operador | B11: =(5000000*12*0.2)/4300 -> 2790.6977 | C11: =0 -> 0 | D11: USD/año | E11: Operador: 5.000.000 COP/mes × 12 meses × 20% dedicación / 4.300 TRM
A12: Supervisión | B12: 8000 | C12: 4000 | D12: USD/año | E12: Base plantilla 2025BC × ratio
A13: Seguros | B13: 4200 | C13: 2800 | D13: USD/año | E13: Base plantilla 2025BC × ratio
A14: Certificaciones | B14: 3500 | C14: 2100 | D14: USD/año | E14: Base plantilla 2025BC × ratio
A15: Emisiones CO2 | B15: =(CargaKW_Real/EficCaldera)*HorasAnio/10.5*1.94*25/1000 -> 10854.458 | C15: =(CargaKW_Real/COP)*HorasAnio*0.201*25/1000 -> 3109.5504 | D15: USD/año | E15: Factor 25 USD/t CO₂
A16: Gestión residuos | B16: 1500 | C16: 250 | D16: USD/año | E16: Base plantilla 2025BC × ratio

Sheet OPEX_DET
A1: Concepto | B1: Sistema Vapor (USD/año) | C1: Bomba Calor (USD/año) | D1: Ahorro (USD/año) | E1: Escalador anual (%)
A2: Costo energía | B2: =OPEX_FACTORES!B4 -> 208189 | C2: =OPEX_FACTORES!C4 -> 64759.814 | D2: =B2-C2 -> 143429.18 | E2: 0.05
A3: Preventivo | B3: =OPEX_FACTORES!B5*OPEX_FACTORES!$G$3 -> 18183.673 | C3: =OPEX_FACTORES!C5*OPEX_FACTORES!$G$3 -> 7576.5306 | D3: =B3-C3 -> 10607.143 | E3: 0.05
A4: Correctivo | B4: =OPEX_FACTORES!B6*OPEX_FACTORES!$G$3 -> 12122.449 | C4: =OPEX_FACTORES!C6*OPEX_FACTORES!$G$3 -> 3838.7755 | D4: =B4-C4 -> 8283.6735 | E4: 0.05
A5: Inspecciones | B5: =OPEX_FACTORES!B7*OPEX_FACTORES!$G$3 -> 8586.7347 | C5: =OPEX_FACTORES!C7*OPEX_FACTORES!$G$3 -> 3232.6531 | D5: =B5-C5 -> 5354.0816 | E5: 0.05
A6: Químicos caldera | B6: =OPEX_FACTORES!B8*OPEX_FACTORES!$G$3 -> 6566.3265 | C6: =OPEX_FACTORES!C8*OPEX_FACTORES!$G$3 -> 0 | D6: =B6-C6 -> 6566.3265 | E6: 0.05
A7: Agua reposición sistema enfriamiento | B7: =OPEX_FACTORES!B9*OPEX_FACTORES!$G$3 -> 15840 | C7: =OPEX_FACTORES!C9*OPEX_FACTORES!$G$3 -> 2161.8367 | D7: =B7-C7 -> 13678.163 | E7: 0.05
A8: Análisis calidad | B8: =OPEX_FACTORES!B10*OPEX_FACTORES!$G$3 -> 3232.6531 | C8: =OPEX_FACTORES!C10*OPEX_FACTORES!$G$3 -> 1818.3673 | D8: =B8-C8 -> 1414.2857 | E8: 0.05
A9: Operador | B9: =OPEX_FACTORES!B11 -> 2790.6977 | C9: =OPEX_FACTORES!C11 -> 0 | D9: =B9-C9 -> 2790.6977 | E9: 0.05
A10: Supervisión | B10: =OPEX_FACTORES!B12*OPEX_FACTORES!$G$3 -> 8081.6327 | C10: =OPEX_FACTORES!C12*OPEX_FACTORES!$G$3 -> 4040.8163 | D10: =B10-C10 -> 4040.8163 | E10: 0.05
A11: Seguros | B11: =OPEX_FACTORES!B13*OPEX_FACTORES!$G$3 -> 4242.8571 | C11: =OPEX_FACTORES!C13*OPEX_FACTORES!$G$3 -> 2828.5714 | D11: =B11-C11 -> 1414.2857 | E11: 0.05
A12: Certificaciones | B12: =OPEX_FACTORES!B14*OPEX_FACTORES!$G$3 -> 3535.7143 | C12: =OPEX_FACTORES!C14*OPEX_FACTORES!$G$3 -> 2121.4286 | D12: =B12-C12 -> 1414.2857 | E12: 0.05
A13: Emisiones CO2 | B13: =OPEX_FACTORES!B15 -> 10854.458 | C13: =OPEX_FACTORES!C15 -> 3109.5504 | D13: =B13-C13 -> 7744.9075 | E13: 0.05
A14: Gestión residuos | B14: =OPEX_FACTORES!B16*OPEX_FACTORES!$G$3 -> 1515.3061 | C14: =OPEX_FACTORES!C16*OPEX_FACTORES!$G$3 -> 252.55102 | D14: =B14-C14 -> 1262.7551 | E14: 0.05
A15: TOTAL OPEX (Ahorro año 1) | D15: =SUM(D2:D14) -> 208000.61

Sheet CF_MODEL
A1: Modelo de Flujo de Caja Descontado
A3: Concepto | B3: 0 | C3: 1 | D3: 2 | E3: 3 | F3: 4 | G3: 5 | H3: 6 | I3: 7 | J3: 8 | K3: 9 | L3: 10 | M3: 11 | N3: 12 | O3: 13 | P3: 14 | Q3: 15
A4: CAPEX (negativo en t=0) | B4: =-CAPEX_TOTAL -> -384561 | C4: 0 | D4: 0 | E4: 0 | F4: 0 | G4: 0 | H4: 0 | I4: 0 | J4: 0 | K4: 0 | L4: 0 | M4: 0 | N4: 0 | O4: 0 | P4: 0 | Q4: 0
A5: Ahorro OPEX (crece %/año) | B5: 0 | C5: =AhorroBase -> 208000.61 | D5: =CF_MODEL!C5*(1+EscOPEX) -> 218400.64 | E5: =CF_MODEL!D5*(1+EscOPEX) -> 229320.67 | F5: =CF_MODEL!E5*(1+EscOPEX) -> 240786.7 | G5: =CF_MODEL!F5*(1+EscOPEX) -> 252826.04 | H5: =CF_MODEL!G5*(1+EscOPEX) -> 265467.34 | I5: =CF_MODEL!H5*(1+EscOPEX) -> 278740.7 | J5: =CF_MODEL!I5*(1+EscOPEX) -> 292677.74 | K5: =CF_MODEL!J5*(1+EscOPEX) -> 307311.63 | ... Q5: =CF_MODEL!P5*(1+EscOPEX) -> 411826.97
A6: Valor residual (año final) | C6: 0 | D6: 0 | E6: 0 | F6: 0 | G6: 0 | H6: 0 | I6: 0 | J6: 0 | K6: 0 | L6: 0 | M6: 0 | N6: 0 | O6: 0 | P6: 0 | Q6: =CAPEX_TOTAL*ValorResidualPct -> 0
A7: Flujo de Caja (FC) | B7: =CF_MODEL!B5+CF_MODEL!B6+CF_MODEL!B4 -> -384561 | C7: =CF_MODEL!C5+CF_MODEL!C6+CF_MODEL!C4 -> 208000.61 | D7: =CF_MODEL!D5+CF_MODEL!D6+CF_MODEL!D4 -> 218400.64 | E7: =CF_MODEL!E5+CF_MODEL!E6+CF_MODEL!E4 -> 229320.67 | F7: =CF_MODEL!F5+CF_MODEL!F6+CF_MODEL!F4 -> 240786.7 | G7: =CF_MODEL!G5+CF_MODEL!G6+CF_MODEL!G4 -> 252826.04 | H7: =CF_MODEL!H5+CF_MODEL!H6+CF_MODEL!H4 -> 265467.34 | I7: =CF_MODEL!I5+CF_MODEL!I6+CF_MODEL!I4 -> 278740.7 | ... Q7: =CF_MODEL!Q5+CF_MODEL!Q6+CF_MODEL!Q4 -> 411826.97
A9: FC Descontado | B9: =CF_MODEL!B7 -> -384561 | C9: =CF_MODEL!C7/(1+WACC)^1 -> 192593.15 | D9: =CF_MODEL!D7/(1+WACC)^2 -> 187243.34 | E9: =CF_MODEL!E7/(1+WACC)^3 -> 182042.14 | F9: =CF_MODEL!F7/(1+WACC)^4 -> 176985.41 | G9: =CF_MODEL!G7/(1+WACC)^5 -> 172069.15 | H9: =CF_MODEL!H7/(1+WACC)^6 -> 167289.45 | I9: =CF_MODEL!I7/(1+WACC)^7 -> 162642.52 | J9: =CF_MODEL!J7/(1+WACC)^8 -> 158124.68 | K9: =CF_MODEL!K7/(1+WACC)^9 -> 153732.32 | L9: =CF_MODEL!L7/(1+WACC)^10 -> 149461.98 | M9: =CF_MODEL!M7/(1+WACC)^11 -> 145310.26 | N9: =CF_MODEL!N7/(1+WACC)^12 -> 141273.86 | O9: =CF_MODEL!O7/(1+WACC)^13 -> 137349.59 | P9: =CF_MODEL!P7/(1+WACC)^14 -> 133534.32 | Q9: =CF_MODEL!Q7/(1+WACC)^15 -> 129825.04
A10: FC Acum. Descontado | B10: =B9 -> -384561 | C10: =CF_MODEL!B10+CF_MODEL!C9 -> -191967.85 | D10: =CF_MODEL!C10+CF_MODEL!D9 -> -4724.5041 | E10: =CF_MODEL!D10+CF_MODEL!E9 -> 177317.63 | F10: =CF_MODEL!E10+CF_MODEL!F9 -> 354303.05 | G10: =CF_MODEL!F10+CF_MODEL!G9 -> 526372.2 | H10: =CF_MODEL!G10+CF_MODEL!H9 -> 693661.65 | I10: =CF_MODEL!H10+CF_MODEL!I9 -> 856304.18 | J10: =CF_MODEL!I10+CF_MODEL!J9 -> 1014428.9 | ... Q10: =CF_MODEL!P10+CF_MODEL!Q9 -> 2004916.2
A13: VPN (suma de FC descontados) | B13: =SUM(B9:Q9) -> 2004916.2
A14: TIR (IRR sobre FC) | B14: =IRR(B7:Q7) -> 0.5898046
A15: Payback (años, descontado) | B15: =IFERROR(COUNTIF(B10:Q10,"<0")-1+ABS(INDEX(B10:Q10,COUNTIF(B10:Q10,"<0")))/INDEX(B9:Q9,COUNTIF(B10:Q10,"<0")+1),"") -> 2.0259528 | C15: Método: interpolación lineal entre último año negativo y primer año positivo del FC acum. descontado

Sheet INDICADORES
A1: Indicadores Financieros
A2: KPI | B2: Valor | C2: Notas
A3: KPI | B3: Valor
A4: VPN (NPV) | B4: =CF_MODEL!B13 -> 2004916.2
A5: TIR (IRR) | B5: =CF_MODEL!B14 -> 0.5898046
A6: Payback descontado (años) | B6: =CF_MODEL!B15 -> 2.0259528
A7: TIR objetivo (%) | B7: =TIR_OBJ -> 0.08
A8: Relación TIR / Objetivo | B8: =IFERROR(B5/B7,0) -> 7.3725575
A10: Resumen
A11: CAPEX base (sin escenario) | B11: =CAPEX_BASE -> 384561
A12: CAPEX total (con escenario) | B12: =CAPEX_TOTAL -> 384561
A13: Ahorro OPEX año 1 | B13: =AhorroBase -> 208000.61
A14: Escenario activo | B14: =ScenarioSel -> Base
A15: Multiplicador CAPEX | B15: =CAPEX_MULT -> 1
A16: Carga térmica diseño (kW) | B16: =CargaKW -> 250
A17: Potencia eléctrica (kW) | B17: =CargaKW/COP -> 83.333333
A18: Horas/año | B18: =HorasAnio -> 7920
A20: Break-even (VPN = 0)
A21: CAPEX máximo para viabilidad | B21: =AhorroBase*((1-((1+EscOPEX)/(1+WACC))^Horizonte)/(WACC-EscOPEX)) -> 2389477.2 | C21: Nota: supone valor residual = 0
A22: Ahorro mínimo año 1 para viabilidad | B22: =CAPEX_TOTAL/((1-((1+EscOPEX)/(1+WACC))^Horizonte)/(WACC-EscOPEX)) -> 33475.49

Sheet SENS
A1: Análisis de Sensibilidad · Δ-VPN ±25 %
Z2: =INDICADORES!B4 -> 2004916.2
A3: Variable | B3: Nivel | C3: CAPEX_mult | D3: Ahorro_mult | E3: WACC_mult | F3: Esc_mult | G3: Horas_mult
A4: CAPEX | B4: Bajo | C4: 0.75 | D4: 1 | E4: 1 | F4: 1 | G4: 1
A5: CAPEX | B5: Alto | C5: 1.25 | D5: 1 | E5: 1 | F5: 1 | G5: 1
A6: Ahorro | B6: Bajo | C6: 1 | D6: 0.75 | E6: 1 | F6: 1 | G6: 1
A7: Ahorro | B7: Alto | C7: 1 | D7: 1.25 | E7: 1 | F7: 1 | G7: 1
A8: WACC | B8: Bajo | C8: 1 | D8: 1 | E8: 0.75 | F8: 1 | G8: 1
A9: WACC | B9: Alto | C9: 1 | D9: 1 | E9: 1.25 | F9: 1 | G9: 1
A10: EscOPEX | B10: Bajo | C10: 1 | D10: 1 | E10: 1 | F10: 0.75 | G10: 1
A11: EscOPEX | B11: Alto | C11: 1 | D11: 1 | E11: 1 | F11: 1.25 | G11: 1
A12: Horas | B12: Bajo | C12: 1 | D12: 1 | E12: 1 | F12: 1 | G12: 0.75
A13: Horas | B13: Alto | C13: 1 | D13: 1 | E13: 1 | F13: 1 | G13: 1.25
A14: (Modelos por caso → IRR/NPV)
A15: t | B15: 0 | C15: 1 | D15: 2 | E15: 3 | F15: 4 | G15: 5 | H15: 6 | I15: 7 | J15: 8 | K15: 9 | L15: 10 | M15: 11 | N15: 12 | O15: 13 | P15: 14 | Q15: 15 | S15: IRR | T15: NPV
B16: =-CAPEX_BASE*$C$4 -> -288420.75 | C16: =AhorroBase*$D$4*$G$4 -> 208000.61 | D16: =SENS!C16*(1+EscOPEX*$F$4) -> 218400.64 | E16: =SENS!D16*(1+EscOPEX*$F$4) -> 229320.67 | F16: =SENS!E16*(1+EscOPEX*$F$4) -> 240786.7 | G16: =SENS!F16*(1+EscOPEX*$F$4) -> 252826.04 | H16: =SENS!G16*(1+EscOPEX*$F$4) -> 265467.34 | I16: =SENS!H16*(1+EscOPEX*$F$4) -> 278740.7 | J16: =SENS!I16*(1+EscOPEX*$F$4) -> 292677.74 | K16: =SENS!J16*(1+EscOPEX*$F$4) -> 307311.63 | ... P16: =SENS!O16*(1+EscOPEX*$F$4) -> 392216.16 | Q16: =SENS!P16*(1+EscOPEX*$F$4) + CAPEX_BASE*ValorResidualPct*$C$4 -> 411826.97 | S16: =IRR(B16:Q16) -> 0.77088694 | T16: =B16+C16/(1+WACC*$E$4)^1+D16/(1+WACC*$E$4)^2+E16/(1+WACC*$E$4)^3+F16/(1+WACC*$E$4)^4+G16/(1+WACC*$E$4)^5+H16/(1+WACC*$E$4)^6+I16/(1+WACC*$E$4)^7+J16/(1+WACC*$E$4)^8+K16/(1+WACC*$E$4)^9+L16/(1+WACC*$E$4)^10+M16/(1+WACC*$E$4)^11+N16/(1+WACC*$E$4)^12+O16/(1+WACC*$E$4)^13+P16/(1+WACC*$E$4)^14+Q16/(1+WACC*$E$4)^15 -> 2101056.5
B17: =-CAPEX_BASE*$C$5 -> -480701.25 | C17: =AhorroBase*$D$5*$G$5 -> 208000.61 | D17: =SENS!C17*(1+EscOPEX*$F$5) -> 218400.64 | E17: =SENS!D17*(1+EscOPEX*$F$5) -> 229320.67 | F17: =SENS!E17*(1+EscOPEX*$F$5) -> 240786.7 | G17: =SENS!F17*(1+EscOPEX*$F$5) -> 252826.04 | H17: =SENS!G17*(1+EscOPEX*$F$5) -> 265467.34 | I17: =SENS!H17*(1+EscOPEX*$F$5) -> 278740.7 | J17: =SENS!I17*(1+EscOPEX*$F$5) -> 292677.74 | K17: =SENS!J17*(1+EscOPEX*$F$5) -> 307311.63 | ... P17: =SENS!O17*(1+EscOPEX*$F$5) -> 392216.16 | Q17: =SENS!P17*(1+EscOPEX*$F$5) + CAPEX_BASE*ValorResidualPct*$C$5 -> 411826.97 | S17: =IRR(B17:Q17) -> 0.48019492 | T17: =B17+C17/(1+WACC*$E$5)^1+D17/(1+WACC*$E$5)^2+E17/(1+WACC*$E$5)^3+F17/(1+WACC*$E$5)^4+G17/(1+WACC*$E$5)^5+H17/(1+WACC*$E$5)^6+I17/(1+WACC*$E$5)^7+J17/(1+WACC*$E$5)^8+K17/(1+WACC*$E$5)^9+L17/(1+WACC*$E$5)^10+M17/(1+WACC*$E$5)^11+N17/(1+WACC*$E$5)^12+O17/(1+WACC*$E$5)^13+P17/(1+WACC*$E$5)^14+Q17/(1+WACC*$E$5)^15 -> 1908776
B18: =-CAPEX_BASE*$C$6 -> -384561 | C18: =AhorroBase*$D$6*$G$6 -> 156000.45 | D18: =SENS!C18*(1+EscOPEX*$F$6) -> 163800.48 | E18: =SENS!D18*(1+EscOPEX*$F$6) -> 171990.5 | F18: =SENS!E18*(1+EscOPEX*$F$6) -> 180590.03 | G18: =SENS!F18*(1+EscOPEX*$F$6) -> 189619.53 | H18: =SENS!G18*(1+EscOPEX*$F$6) -> 199100.5 | I18: =SENS!H18*(1+EscOPEX*$F$6) -> 209055.53 | J18: =SENS!I18*(1+EscOPEX*$F$6) -> 219508.3 | K18: =SENS!J18*(1+EscOPEX*$F$6) -> 230483.72 | ... P18: =SENS!O18*(1+EscOPEX*$F$6) -> 294162.12 | Q18: =SENS!P18*(1+EscOPEX*$F$6) + CAPEX_BASE*ValorResidualPct*$C$6 -> 308870.23 | S18: =IRR(B18:Q18) -> 0.45253906 | T18: =B18+C18/(1+WACC*$E$6)^1+D18/(1+WACC*$E$6)^2+E18/(1+WACC*$E$6)^3+F18/(1+WACC*$E$6)^4+G18/(1+WACC*$E$6)^5+H18/(1+WACC*$E$6)^6+I18/(1+WACC*$E$6)^7+J18/(1+WACC*$E$6)^8+K18/(1+WACC*$E$6)^9+L18/(1+WACC*$E$6)^10+M18/(1+WACC*$E$6)^11+N18/(1+WACC*$E$6)^12+O18/(1+WACC*$E$6)^13+P18/(1+WACC*$E$6)^14+Q18/(1+WACC*$E$6)^15 -> 1407546.9
B19: =-CAPEX_BASE*$C$7 -> -384561 | C19: =AhorroBase*$D$7*$G$7 -> 260000.76 | D19: =SENS!C19*(1+EscOPEX*$F$7) -> 273000.79 | E19: =SENS!D19*(1+EscOPEX*$F$7) -> 286650.83 | F19: =SENS!E19*(1+EscOPEX*$F$7) -> 300983.38 | G19: =SENS!F19*(1+EscOPEX*$F$7) -> 316032.54 | H19: =SENS!G19*(1+EscOPEX*$F$7) -> 331834.17 | I19: =SENS!H19*(1+EscOPEX*$F$7) -> 348425.88 | J19: =SENS!I19*(1+EscOPEX*$F$7) -> 365847.17 | K19: =SENS!J19*(1+EscOPEX*$F$7) -> 384139.53 | ... P19: =SENS!O19*(1+EscOPEX*$F$7) -> 490270.2 | Q19: =SENS!P19*(1+EscOPEX*$F$7) + CAPEX_BASE*ValorResidualPct*$C$7 -> 514783.71 | S19: =IRR(B19:Q19) -> 0.72570551 | T19: =B19+C19/(1+WACC*$E$7)^1+D19/(1+WACC*$E$7)^2+E19/(1+WACC*$E$7)^3+F19/(1+WACC*$E$7)^4+G19/(1+WACC*$E$7)^5+H19/(1+WACC*$E$7)^6+I19/(1+WACC*$E$7)^7+J19/(1+WACC*$E$7)^8+K19/(1+WACC*$E$7)^9+L19/(1+WACC*$E$7)^10+M19/(1+WACC*$E$7)^11+N19/(1+WACC*$E$7)^12+O19/(1+WACC*$E$7)^13+P19/(1+WACC*$E$7)^14+Q19/(1+WACC*$E$7)^15 -> 2602285.5
B20: =-CAPEX_BASE*$C$8 -> -384561 | C20: =AhorroBase*$D$8*$G$8 -> 208000.61 | D20: =SENS!C20*(1+EscOPEX*$F$8) -> 218400.64 | E20: =SENS!D20*(1+EscOPEX*$F$8) -> 229320.67 | F20: =SENS!E20*(1+EscOPEX*$F$8) -> 240786.7 | G20: =SENS!F20*(1+EscOPEX*$F$8) -> 252826.04 | H20: =SENS!G20*(1+EscOPEX*$F$8) -> 265467.34 | I20: =SENS!H20*(1+EscOPEX*$F$8) -> 278740.7 | J20: =SENS!I20*(1+EscOPEX*$F$8) -> 292677.74 | K20: =SENS!J20*(1+EscOPEX*$F$8) -> 307311.63 | ... P20: =SENS!O20*(1+EscOPEX*$F$8) -> 392216.16 | Q20: =SENS!P20*(1+EscOPEX*$F$8) + CAPEX_BASE*ValorResidualPct*$C$8 -> 411826.97 | S20: =IRR(B20:Q20) -> 0.5898046 | T20: =B20+C20/(1+WACC*$E$8)^1+D20/(1+WACC*$E$8)^2+E20/(1+WACC*$E$8)^3+F20/(1+WACC*$E$8)^4+G20/(1+WACC*$E$8)^5+H20/(1+WACC*$E$8)^6+I20/(1+WACC*$E$8)^7+J20/(1+WACC*$E$8)^8+K20/(1+WACC*$E$8)^9+L20/(1+WACC*$E$8)^10+M20/(1+WACC*$E$8)^11+N20/(1+WACC*$E$8)^12+O20/(1+WACC*$E$8)^13+P20/(1+WACC*$E$8)^14+Q20/(1+WACC*$E$8)^15 -> 2372193.9
B21: =-CAPEX_BASE*$C$9 -> -384561 | C21: =AhorroBase*$D$9*$G$9 -> 208000.61 | D21: =SENS!C21*(1+EscOPEX*$F$9) -> 218400.64 | E21: =SENS!D21*(1+EscOPEX*$F$9) -> 229320.67 | F21: =SENS!E21*(1+EscOPEX*$F$9) -> 240786.7 | G21: =SENS!F21*(1+EscOPEX*$F$9) -> 252826.04 | H21: =SENS!G21*(1+EscOPEX*$F$9) -> 265467.34 | I21: =SENS!H21*(1+EscOPEX*$F$9) -> 278740.7 | J21: =SENS!I21*(1+EscOPEX*$F$9) -> 292677.74 | K21: =SENS!J21*(1+EscOPEX*$F$9) -> 307311.63 | ... P21: =SENS!O21*(1+EscOPEX*$F$9) -> 392216.16 | Q21: =SENS!P21*(1+EscOPEX*$F$9) + CAPEX_BASE*ValorResidualPct*$C$9 -> 411826.97 | S21: =IRR(B21:Q21) -> 0.5898046 | T21: =B21+C21/(1+WACC*$E$9)^1+D21/(1+WACC*$E$9)^2+E21/(1+WACC*$E$9)^3+F21/(1+WACC*$E$9)^4+G21/(1+WACC*$E$9)^5+H21/(1+WACC*$E$9)^6+I21/(1+WACC*$E$9)^7+J21/(1+WACC*$E$9)^8+K21/(1+WACC*$E$9)^9+L21/(1+WACC*$E$9)^10+M21/(1+WACC*$E$9)^11+N21/(1+WACC*$E$9)^12+O21/(1+WACC*$E$9)^13+P21/(1+WACC*$E$9)^14+Q21/(1+WACC*$E$9)^15 -> 1705100.9
B22: =-CAPEX_BASE*$C$10 -> -384561 | C22: =AhorroBase*$D$10*$G$10 -> 208000.61 | D22: =SENS!C22*(1+EscOPEX*$F$10) -> 215800.63 | E22: =SENS!D22*(1+EscOPEX*$F$10) -> 223893.15 | F22: =SENS!E22*(1+EscOPEX*$F$10) -> 232289.14 | G22: =SENS!F22*(1+EscOPEX*$F$10) -> 240999.99 | H22: =SENS!G22*(1+EscOPEX*$F$10) -> 250037.49 | I22: =SENS!H22*(1+EscOPEX*$F$10) -> 259413.89 | J22: =SENS!I22*(1+EscOPEX*$F$10) -> 269141.91 | K22: =SENS!J22*(1+EscOPEX*$F$10) -> 279234.74 | ... P22: =SENS!O22*(1+EscOPEX*$F$10) -> 335668.02 | Q22: =SENS!P22*(1+EscOPEX*$F$10) + CAPEX_BASE*ValorResidualPct*$C$10 -> 348255.57 | S22: =IRR(B22:Q22) -> 0.57736898 | T22: =B22+C22/(1+WACC*$E$10)^1+D22/(1+WACC*$E$10)^2+E22/(1+WACC*$E$10)^3+F22/(1+WACC*$E$10)^4+G22/(1+WACC*$E$10)^5+H22/(1+WACC*$E$10)^6+I22/(1+WACC*$E$10)^7+J22/(1+WACC*$E$10)^8+K22/(1+WACC*$E$10)^9+L22/(1+WACC*$E$10)^10+M22/(1+WACC*$E$10)^11+N22/(1+WACC*$E$10)^12+O22/(1+WACC*$E$10)^13+P22/(1+WACC*$E$10)^14+Q22/(1+WACC*$E$10)^15 -> 1829533.1
B23: =-CAPEX_BASE*$C$11 -> -384561 | C23: =AhorroBase*$D$11*$G$11 -> 208000.61 | D23: =SENS!C23*(1+EscOPEX*$F$11) -> 221000.64 | E23: =SENS!D23*(1+EscOPEX*$F$11) -> 234813.18 | F23: =SENS!E23*(1+EscOPEX*$F$11) -> 249489.01 | G23: =SENS!F23*(1+EscOPEX*$F$11) -> 265082.07 | H23: =SENS!G23*(1+EscOPEX*$F$11) -> 281649.7 | I23: =SENS!H23*(1+EscOPEX*$F$11) -> 299252.81 | J23: =SENS!I23*(1+EscOPEX*$F$11) -> 317956.11 | K23: =SENS!J23*(1+EscOPEX*$F$11) -> 337828.36 | ... P23: =SENS!O23*(1+EscOPEX*$F$11) -> 457447.02 | Q23: =SENS!P23*(1+EscOPEX*$F$11) + CAPEX_BASE*ValorResidualPct*$C$11 -> 486037.46 | S23: =IRR(B23:Q23) -> 0.60223746 | T23: =B23+C23/(1+WACC*$E$11)^1+D23/(1+WACC*$E$11)^2+E23/(1+WACC*$E$11)^3+F23/(1+WACC*$E$11)^4+G23/(1+WACC*$E$11)^5+H23/(1+WACC*$E$11)^6+I23/(1+WACC*$E$11)^7+J23/(1+WACC*$E$11)^8+K23/(1+WACC*$E$11)^9+L23/(1+WACC*$E$11)^10+M23/(1+WACC*$E$11)^11+N23/(1+WACC*$E$11)^12+O23/(1+WACC*$E$11)^13+P23/(1+WACC*$E$11)^14+Q23/(1+WACC*$E$11)^15 -> 2198588.9
B24: =-CAPEX_BASE*$C$12 -> -384561 | C24: =AhorroBase*$D$12*$G$12 -> 156000.45 | D24: =SENS!C24*(1+EscOPEX*$F$12) -> 163800.48 | E24: =SENS!D24*(1+EscOPEX*$F$12) -> 171990.5 | F24: =SENS!E24*(1+EscOPEX*$F$12) -> 180590.03 | G24: =SENS!F24*(1+EscOPEX*$F$12) -> 189619.53 | H24: =SENS!G24*(1+EscOPEX*$F$12) -> 199100.5 | I24: =SENS!H24*(1+EscOPEX*$F$12) -> 209055.53 | J24: =SENS!I24*(1+EscOPEX*$F$12) -> 219508.3 | K24: =SENS!J24*(1+EscOPEX*$F$12) -> 230483.72 | ... P24: =SENS!O24*(1+EscOPEX*$F$12) -> 294162.12 | Q24: =SENS!P24*(1+EscOPEX*$F$12) + CAPEX_BASE*ValorResidualPct*$C$12 -> 308870.23 | S24: =IRR(B24:Q24) -> 0.45253906 | T24: =B24+C24/(1+WACC*$E$12)^1+D24/(1+WACC*$E$12)^2+E24/(1+WACC*$E$12)^3+F24/(1+WACC*$E$12)^4+G24/(1+WACC*$E$12)^5+H24/(1+WACC*$E$12)^6+I24/(1+WACC*$E$12)^7+J24/(1+WACC*$E$12)^8+K24/(1+WACC*$E$12)^9+L24/(1+WACC*$E$12)^10+M24/(1+WACC*$E$12)^11+N24/(1+WACC*$E$12)^12+O24/(1+WACC*$E$12)^13+P24/(1+WACC*$E$12)^14+Q24/(1+WACC*$E$12)^15 -> 1407546.9
B25: =-CAPEX_BASE*$C$13 -> -384561 | C25: =AhorroBase*$D$13*$G$13 -> 260000.76 | D25: =SENS!C25*(1+EscOPEX*$F$13) -> 273000.79 | E25: =SENS!D25*(1+EscOPEX*$F$13) -> 286650.83 | F25: =SENS!E25*(1+EscOPEX*$F$13) -> 300983.38 | G25: =SENS!F25*(1+EscOPEX*$F$13) -> 316032.54 | H25: =SENS!G25*(1+EscOPEX*$F$13) -> 331834.17 | I25: =SENS!H25*(1+EscOPEX*$F$13) -> 348425.88 | J25: =SENS!I25*(1+EscOPEX*$F$13) -> 365847.17 | K25: =SENS!J25*(1+EscOPEX*$F$13) -> 384139.53 | ... P25: =SENS!O25*(1+EscOPEX*$F$13) -> 490270.2 | Q25: =SENS!P25*(1+EscOPEX*$F$13) + CAPEX_BASE*ValorResidualPct*$C$13 -> 514783.71 | S25: =IRR(B25:Q25) -> 0.72570551 | T25: =B25+C25/(1+WACC*$E$13)^1+D25/(1+WACC*$E$13)^2+E25/(1+WACC*$E$13)^3+F25/(1+WACC*$E$13)^4+G25/(1+WACC*$E$13)^5+H25/(1+WACC*$E$13)^6+I25/(1+WACC*$E$13)^7+J25/(1+WACC*$E$13)^8+K25/(1+WACC*$E$13)^9+L25/(1+WACC*$E$13)^10+M25/(1+WACC*$E$13)^11+N25/(1+WACC*$E$13)^12+O25/(1+WACC*$E$13)^13+P25/(1+WACC*$E$13)^14+Q25/(1+WACC*$E$13)^15 -> 2602285.5
A27: Resumen (∆VPN vs Base)
A28: Variable | B28: Low ∆NPV | C28: High ∆NPV
A29: CAPEX | B29: =SENS!T16-SENS!Z$2 -> 96140.25 | C29: =SENS!T17-SENS!Z$2 -> -96140.25
A30: Ahorro | B30: =SENS!T18-SENS!Z$2 -> -597369.31 | C30: =SENS!T19-SENS!Z$2 -> 597369.31
A31: WACC | B31: =SENS!T20-SENS!Z$2 -> 367277.66 | C31: =SENS!T21-SENS!Z$2 -> -299815.28
A32: EscOPEX | B32: =SENS!T22-SENS!Z$2 -> -175383.13 | C32: =SENS!T23-SENS!Z$2 -> 193672.68
A33: Horas | B33: =SENS!T24-SENS!Z$2 -> -597369.31 | C33: =SENS!T25-SENS!Z$2 -> 597369.31

Sheet _AUX
A1: CAPEX por disciplina | D1: OPEX por categoría | H1: Emisiones y ambiente | N1: Escenarios resumen | S1: Matriz viabilidad VPN (CAPEX vs Ahorro) | AC1: Sensibilidad Scatter | AF1: FC acumulado por escenario | AJ1: FC brutos escenarios | AL1: Ahorro acumulado (sin descontar) | AO1: Payback benchmark | AR1: Radar normalizado
A2: Disciplina | B2: Subtotal (USD) | D2: Categoría | E2: Gas (USD) | F2: BC (USD) | H2: Concepto | I2: Gas | J2: BC | K2: Unidad | N2: Escenario | O2: VPN | P2: TIR | Q2: Payback | S2: CAPEX \ Ahorro | T2: 0.75x | U2: 1.00x | V2: 1.25x | AC2: NPV | AD2: IRR | AF2: Año | AG2: Pesimista | AH2: Base | AI2: Optimista | AJ2: Año | AK2: Pesimista | AL2: Año | AM2: Acumulado | AO2: Concepto | AP2: Valor | AR2: Dimensión | AS2: Caldera | AT2: BC
A3: Equipos principales | B3: 185000 | D3: Energía | E3: 208189.07 | F3: 64759.814 | H3: Emisiones CO2 (t/año) | I3: 434.17831 | J3: 124.38202 | K3: tCO2/año | N3: Pesimista | O3: 1229217.3 | P3: 0.050363501 | Q3: 2.5 | S3: 1453488.8 | T3: 2049290.8 | U3: 2645092.7 | AC3: 2155537.1 | AD3: 0.073820061 | AF3: 0 | AG3: -333917.1 | AH3: -303561 | AI3: -273204.9 | AJ3: 0 | AK3: -333917.1 | AL3: -303561 | AM3: 0 | AO3: Actual | AP3: 1.5969046 | AR3: Energía | AS3: 1 | AT3: 0.3110625
A4: Instrumentación y control | B4: 5000 | D4: Mantenimiento | E4: 38500 | F4: 14500 | H4: Gas natural evitado (m3/año) | I4: 223803.25 | J4: 0 | K4: m3/año | N4: Base | O4: 2079646.9 | P4: 0.054941394 | Q4: 1.5969046 | S4: 1483844.9 | T4: 2079646.9 | U4: 2675448.8 | AC4: 2003756.6 | AD4: 0.04054528 | AF4: 1 | AG4: -192470.6 | AH4: -111473.16 | AI4: -28564.728 | AJ4: 1 | AK4: 155591.15 | AL4: 1 | AM4: 207454.87 | AO4: Benchmark mínimo | AP4: 3 | AR4: Mantenimiento | AS4: 0.18492805 | AT4: 0.069648227
A5: Logística y aduanas | B5: 22000 | D5: Servicios y consumibles | E5: 28170.698 | F5: 3940 | H5: Equivalente árboles plantados | I5: 13940.833 | K5: árboles/año | N5: Optimista | O5: 3163697.4 | P5: 0.056528393 | Q5: 1.2 | S5: 1514201 | T5: 2110003 | U5: 2705804.9 | AC5: 1483844.9 | AD5: 0.036421347 | AF5: 2 | AG5: -57453.488 | AH5: 75278.904 | AI5: 213767.52 | AJ5: 2 | AK5: 163370.71 | AL5: 2 | AM5: 425282.47 | AO5: Benchmark máximo | AP5: 10 | AR5: Servicios | AS5: 0.13531305 | AT5: 0.018925105
A6: Sistemas auxiliares | B6: 24075 | D6: Personal | E6: 2790.6977 | F6: 0 | AC6: 2675448.8 | AD6: 0.069553268 | AF6: 3 | AG6: 71426.484 | AH6: 256843.41 | AI6: 453813.61 | AJ6: 3 | AK6: 171539.24 | AL6: 3 | AM6: 654001.46 | AO6: Límite aceptable | AP6: 5 | AR6: Personal | AS6: 0.013404631 | AT6: 0
A7: Ingeniería | B7: 5000 | D7: Seguros y certificaciones | E7: 7700 | F7: 4900 | AC7: 2445960.9 | AD7: 0.034941394 | AF7: 4 | AG7: 194448.27 | AH7: 433364.46 | AI7: 691595.12 | AJ7: 4 | AK7: 180116.2 | AL7: 4 | AM7: 894156.4 | AR7: Seguros/Cert | AS7: 0.03698561 | AT7: 0.023536298
A8: Instalación | B8: 25000 | D8: Ambiental | E8: 12354.458 | F8: 3359.5504 | AC8: 1780618.2 | AD8: 0.074941394 | AF8: 5 | AG8: 311878.17 | AH8: 604982.15 | AI8: 927133.4 | AJ8: 5 | AK8: 189122.01 | AL8: 5 | AM8: 1146319.1 | AR8: Ambiental | AS8: 0.059342489 | AT8: 0.016137016
A9: Puesta en marcha | B9: 15000 | AC9: 2079646.9 | AD9: 0.054941394 | AF9: 6 | AG9: 423970.33 | AH9: 771832.68 | AI9: 1160449.6 | AJ9: 6 | AK9: 198578.11 | AL9: 6 | AM9: 1411089.9
AC10: 2079646.9 | AD10: 0.054941394 | AF10: 7 | AG10: 530967.41 | AH10: 934048.47 | AI10: 1391564.8 | AJ10: 7 | AK10: 208507.02 | AL10: 7 | AM10: 1689099.3
AC11: 1483844.9 | AD11: 0.036421347 | AF11: 8 | AG11: 633100.97 | AH11: 1091758.3 | AI11: 1620499.6 | AJ11: 8 | AK11: 218932.37 | AL11: 8 | AM11: 1981009.1
AC12: 2675448.8 | AD12: 0.069553268 | AF12: 9 | AG12: 730592.1 | AH12: 1245087.2 | AI12: 1847274.6 | AJ12: 9 | AK12: 229878.99 | AL12: 9 | AM12: 2287514.4
AF13: 10 | AG13: 823651.82 | AH13: 1394157.1 | AI13: 2071910.2 | AJ13: 10 | AK13: 241372.94 | AL13: 10 | AM13: 2609345
AF14: 11 | AG14: 912481.55 | AH14: 1539086.1 | AI14: 2294426.7 | AJ14: 11 | AK14: 253441.59 | AL14: 11 | AM14: 2947267.1
AF15: 12 | AG15: 997273.57 | AH15: 1679989.3 | AI15: 2514843.9 | AJ15: 12 | AK15: 266113.67 | AL15: 12 | AM15: 3302085.3
AF16: 13 | AG16: 1078211.4 | AH16: 1816978.5 | AI16: 2733181.7 | AJ16: 13 | AK16: 279419.35 | AL16: 13 | AM16: 3674644.5
AF17: 14 | AG17: 1155470.2 | AH17: 1950162.5 | AI17: 2949459.8 | AJ17: 14 | AK17: 293390.32 | AL17: 14 | AM17: 4065831.6
AF18: 15 | AG18: 1229217.3 | AH18: 2079646.9 | AI18: 3163697.4 | AJ18: 15 | AK18: 308059.83 | AL18: 15 | AM18: 4476578

Sheet _DATA_VIZ
A1: Disciplina | B1: Subtotal | D1: Escenario | E1: VPN | F1: TIR | G1: Payback | I1: Año | J1: FC desc. acumulado (Base)
A2: Equipos principales | B2: =_AUX!B5 -> 22000 | D2: Pesimista | E2: =_AUX!O3 -> 1229217.3 | F2: =_AUX!P3 -> 0.050363501 | G2: =_AUX!Q3 -> 2.5 | I2: 0 | J2: =CF_MODEL!B10 -> -384561
A3: Instrumentación y control | B3: =_AUX!B6 -> 24075 | D3: Base | E3: =INDICADORES!B4 -> 2004916.2 | F3: =INDICADORES!B5 -> 0.5898046 | G3: =INDICADORES!B6 -> 2.0259528 | I3: 1 | J3: =CF_MODEL!C10 -> -191967.85
A4: Logística y aduanas | B4: =_AUX!B7 -> 5000 | D4: Optimista | E4: =_AUX!O5 -> 3163697.4 | F4: =_AUX!P5 -> 0.056528393 | G4: =_AUX!Q5 -> 1.2 | I4: 2 | J4: =CF_MODEL!D10 -> -4724.5041
A5: Sistemas auxiliares | B5: =_AUX!B8 -> 25000 | I5: 3 | J5: =CF_MODEL!E10 -> 177317.63
A6: Ingeniería | B6: =_AUX!B9 -> 15000 | I6: 4 | J6: =CF_MODEL!F10 -> 354303.05
A7: Instalación | B7: =_AUX!B10 -> 0 | I7: 5 | J7: =CF_MODEL!G10 -> 526372.2
A8: Puesta en marcha | B8: =_AUX!B11 -> 0 | I8: 6 | J8: =CF_MODEL!H10 -> 693661.65
I9: 7 | J9: =CF_MODEL!I10 -> 856304.18
I10: 8 | J10: =CF_MODEL!J10 -> 1014428.9
I11: 9 | J11: =CF_MODEL!K10 -> 1168161.2
I12: 10 | J12: =CF_MODEL!L10 -> 1317623.2
I13: 11 | J13: =CF_MODEL!M10 -> 1462933.4
I14: 12 | J14: =CF_MODEL!N10 -> 1604207.3
I15: 13 | J15: =CF_MODEL!O10 -> 1741556.9
I16: 14 | J16: =CF_MODEL!P10 -> 1875091.2
I17: 15 | J17: =CF_MODEL!Q10 -> 2004916.2
A20: Año | B20: FC anual | C20: FC desc. acum. | E20: Variable | F20: Low (-25%) | G20: High (+25%)
A21: 0 | B21: =CF_MODEL!B9 -> -384561 | C21: =CF_MODEL!B10 -> -384561 | E21: CAPEX | F21: =SENS!B29 -> 96140.25 | G21: =SENS!C29 -> -96140.25
A22: 1 | B22: =CF_MODEL!C9 -> 192593.15 | C22: =CF_MODEL!C10 -> -191967.85 | E22: Ahorro | F22: =SENS!B30 -> -597369.31 | G22: =SENS!C30 -> 597369.31
A23: 2 | B23: =CF_MODEL!D9 -> 187243.34 | C23: =CF_MODEL!D10 -> -4724.5041 | E23: WACC | F23: =SENS!B31 -> 367277.66 | G23: =SENS!C31 -> -299815.28
A24: 3 | B24: =CF_MODEL!E9 -> 182042.14 | C24: =CF_MODEL!E10 -> 177317.63 | E24: EscOPEX | F24: =SENS!B32 -> -175383.13 | G24: =SENS!C32 -> 193672.68
A25: 4 | B25: =CF_MODEL!F9 -> 176985.41 | C25: =CF_MODEL!F10 -> 354303.05 | E25: Horas | F25: =SENS!B33 -> -597369.31 | G25: =SENS!C33 -> 597369.31
A26: 5 | B26: =CF_MODEL!G9 -> 172069.15 | C26: =CF_MODEL!G10 -> 526372.2
A27: 6 | B27: =CF_MODEL!H9 -> 167289.45 | C27: =CF_MODEL!H10 -> 693661.65
A28: 7 | B28: =CF_MODEL!I9 -> 162642.52 | C28: =CF_MODEL!I10 -> 856304.18
A29: 8 | B29: =CF_MODEL!J9 -> 158124.68 | C29: =CF_MODEL!J10 -> 1014428.9
A30: 9 | B30: =CF_MODEL!K9 -> 153732.32 | C30: =CF_MODEL!K10 -> 1168161.2
A31: 10 | B31: =CF_MODEL!L9 -> 149461.98 | C31: =CF_MODEL!L10 -> 1317623.2
A32: 11 | B32: =CF_MODEL!M9 -> 145310.26 | C32: =CF_MODEL!M10 -> 1462933.4
A33: 12 | B33: =CF_MODEL!N9 -> 141273.86 | C33: =CF_MODEL!N10 -> 1604207.3
A34: 13 | B34: =CF_MODEL!O9 -> 137349.59 | C34: =CF_MODEL!O10 -> 1741556.9
A35: 14 | B35: =CF_MODEL!P9 -> 133534.32 | C35: =CF_MODEL!P10 -> 1875091.2
A36: 15 | B36: =CF_MODEL!Q9 -> 129825.04 | C36: =CF_MODEL!Q10 -> 2004916.2
A40: Categoría | B40: Caldera | C40: Bomba calor | E40: Categoría | F40: BC (USD) | H40: Dimensión | I40: Caldera | J40: BC
A41: Energía | B41: =OPEX_DET!B2 -> 208189 | C41: =OPEX_DET!C2 -> 64759.814 | E41: Energía | F41: =OPEX_DET!C2 -> 64759.814 | H41: Energía | I41: =_AUX!AS5 -> 0.13531305 | J41: =_AUX!AT5 -> 0.018925105
A42: Mantenimiento | B42: =OPEX_DET!B3+OPEX_DET!B4+OPEX_DET!B5 -> 38892.857 | C42: =OPEX_DET!C3+OPEX_DET!C4+OPEX_DET!C5 -> 14647.959 | E42: Mantenimiento | F42: =OPEX_DET!C3+OPEX_DET!C4+OPEX_DET!C5 -> 14647.959 | H42: Mantenimiento | I42: =_AUX!AS6 -> 0.013404631 | J42: =_AUX!AT6 -> 0
A43: Químicos+Agua | B43: =OPEX_DET!B6+OPEX_DET!B7 -> 22406.327 | C43: =OPEX_DET!C6+OPEX_DET!C7 -> 2161.8367 | E43: Químicos+Agua | F43: =OPEX_DET!C6+OPEX_DET!C7 -> 2161.8367 | H43: Servicios | I43: =_AUX!AS7 -> 0.03698561 | J43: =_AUX!AT7 -> 0.023536298
A44: Análisis | B44: =OPEX_DET!B8 -> 3232.6531 | C44: =OPEX_DET!C8 -> 1818.3673 | E44: Análisis | F44: =OPEX_DET!C8 -> 1818.3673 | H44: Personal | I44: =_AUX!AS8 -> 0.059342489 | J44: =_AUX!AT8 -> 0.016137016
A45: Personal | B45: =OPEX_DET!B9+OPEX_DET!B10 -> 10872.33 | C45: =OPEX_DET!C9+OPEX_DET!C10 -> 4040.8163 | E45: Personal | F45: =OPEX_DET!C9+OPEX_DET!C10 -> 4040.8163 | H45: Seguros/Cert | I45: =_AUX!AS9 -> 0 | J45: =_AUX!AT9 -> 0
...

Sheet DEFAULTS
A1: Valores por defecto del estudio (para RESET)
A3: Variable | B3: Valor
A4: Horizonte (años) | B4: 15
A5: WACC (tasa descuento nominal) | B5: 0.08
A6: Tasa de impuesto efectiva | B6: 0
A7: Valor residual sobre CAPEX | B7: 0
A8: Carga térmica de diseño (kW) | B8: 250
A9: Carga térmica real (kW) | B9: 234.4
A10: COP conservador (adim.) | B10: 3
A11: Horas/año | B11: 7920
A12: Precio electricidad (USD/kWh) | B12: 0.10465116
A13: Escalamiento anual ahorro (%) | B13: 0.05
A14: TIR objetivo (%) | B14: 0.08
A15: Eficiencia caldera referencia | B15: 0.79
A16: Precio gas natural (USD/kWh eq.) | B16: 0.088593577

Sheet SCENARIOS
A1: Perfiles de escenario
A3: Escenario | B3: CAPEX Mult | C3: Escalamiento ahorro | D3: WACC | E3: Valor Residual
A4: Pesimista | B4: 1.1 | C4: 0.03 | D4: 0.1 | E4: 0
A5: Base | B5: 1 | C5: 0.05 | D5: 0.08 | E5: 0
A6: Optimista | B6: 0.9 | C6: 0.07 | D6: 0.06 | E6: 0.15
